Workbook

Sheet 01-VP_VF
B1: © Escola de Imóveis - www.escoladeimoveis.com.br | Siga no instagram e tenha o melhor conteúdo: @escoladeimoveis
B2: É terminantemente proibida a utilização, acesso, cópia ou divulgação não autorizada das informações presentes nesta planilha.
B3: ATENÇÃO: SOMENTE ALTERAR AS CÉLULAS ROXAS COM A ESCRITA FAÇA VOCÊ
B5: Valor Presente (VP ou PV)
B7: Ex 1.0 | C7: Faça Você | D7: Resposta | F7: Ex 1.1 | G7: Faça Você | H7: Resposta
B8: Valor Futuro | D8: 60000 | F8: Valor Futuro | H8: 19900
B9: Período | D9: 10 | F9: Período | H9: 18
B10: Taxa | D10: 0.05 | F10: Taxa | H10: 0.0115
B11: Valor Presente | D11: =-(PV(D10,D9,,D8)) -> 36834.795 | F11: Valor Presente | H11: =-(PV(H10,H9,,H8)) -> 16198.213
B13: Valor Futuro (VF ou FV)
B15: Ex 2.0 | C15: Faça Você | D15: Resposta | F15: Ex 2.1 | G15: Faça Você | H15: Resposta
B16: Valor Presente | D16: 36834.8 | F16: Valor Presente | H16: 16198.21
B17: Período | D17: 10 | F17: Período | H17: 18
B18: Taxa | D18: 0.05 | F18: Taxa | H18: 0.0115
B19: Valor Futuro | D19: =-(FV(D18,D17,,D16)) -> 60000.008 | F19: Valor Futuro | H19: =-(FV(H18,H17,,H16)) -> 19899.996

Sheet 02-VPL
B1: © Escola de Imóveis - www.escoladeimoveis.com.br | Siga no instagram e tenha o melhor conteúdo: @escoladeimoveis
B2: É terminantemente proibida a utilização, acesso, cópia ou divulgação não autorizada das informações presentes nesta planilha.
B3: ATENÇÃO: SOMENTE ALTERAR AS CÉLULAS ROXAS COM A ESCRITA FAÇA VOCÊ
B5: Valor Presente LÍquido (VPL ou NPV)
B7: Ex 1.0 | C7: Faça Você | D7: Resposta | G7: 2020 | H7: 2021 | I7: 2022 | J7: 2023 | K7: 2025 | L7: 2026 | M7: 2034
B8: Custo de Capital | D8: 0.06 | F8: Investimento | G8: -100000
B9: VPL | D9: {=NPV(D8,H11:M11)+G11} -> 90165.351 | F9: Renda | H9: 10000 | I9: 10000 | J9: 10000 | K9: 10000 | L9: 10000 | M9: 10000
F10: Venda | M10: 200000
G11: =SUM(G8:G10) -> -100000 | H11: =SUM(H8:H10) -> 10000 | I11: =SUM(I8:I10) -> 10000 | J11: =SUM(J8:J10) -> 10000 | K11: =SUM(K8:K10) -> 10000 | L11: =SUM(L8:L10) -> 10000 | M11: =SUM(M8:M10) -> 210000
B15: Ex 2.0 | C15: Faça Você | D15: Resposta | G15: 2020 | H15: 2021 | I15: 2022 | J15: 2023 | K15: 2025 | L15: 2026 | M15: 2027
B16: Custo de Capital | D16: 0.08 | F16: Investimento | G16: -235000
B17: VPL | D17: {=NPV(D16,H19:M19)+G19} -> -4744.4971 | F17: Renda | H17: 8000 | I17: 9000 | J17: 10000 | K17: 11000 | L17: 12000 | M17: 13000
F18: Venda | M18: 290000
G19: =SUM(G16:G18) -> -235000 | H19: =SUM(H16:H18) -> 8000 | I19: =SUM(I16:I18) -> 9000 | J19: =SUM(J16:J18) -> 10000 | K19: =SUM(K16:K18) -> 11000 | L19: =SUM(L16:L18) -> 12000 | M19: =SUM(M16:M18) -> 303000
B23: Ex 2.0 | C23: Faça Você | D23: Resposta | G23: 2020 | H23: 2021 | I23: 2022 | J23: 2023 | K23: 2025 | L23: 2026 | M23: 2027
B24: Custo de Capital | D24: 0.095 | F24: Investimento | G24: -90000
B25: VPL | D25: {=NPV(D24,H27:M27)+G27} -> 7519.4105 | F25: Renda | H25: 5000 | I25: 5500 | J25: 6000 | K25: 8000 | L25: 9000 | M25: 10000
F26: Venda | M26: 115000
G27: =SUM(G24:G26) -> -90000 | H27: =SUM(H24:H26) -> 5000 | I27: =SUM(I24:I26) -> 5500 | J27: =SUM(J24:J26) -> 6000 | K27: =SUM(K24:K26) -> 8000 | L27: =SUM(L24:L26) -> 9000 | M27: =SUM(M24:M26) -> 125000

Sheet 03-TIR
B1: © Escola de Imóveis - www.escoladeimoveis.com.br | Siga no instagram e tenha o melhor conteúdo: @escoladeimoveis
B2: É terminantemente proibida a utilização, acesso, cópia ou divulgação não autorizada das informações presentes nesta planilha.
B3: ATENÇÃO: SOMENTE ALTERAR AS CÉLULAS ROXAS COM A ESCRITA FAÇA VOCÊ
B5: Taxa Interna de Retorno (TIR ou IRR)
B7: Ex 1.0 | C7: Faça Você | D7: Resposta | G7: 2020 | H7: 2021 | I7: 2022 | J7: 2023 | K7: 2025 | L7: 2026 | M7: 2027
B8: Custo de Capital | D8: 0.06 | F8: Investimento | G8: -100000
B9: VPL | D9: {=NPV(D8,H11:M11)+G11} -> 90165.351 | F9: Renda | H9: 10000 | I9: 10000 | J9: 10000 | K9: 10000 | L9: 10000 | M9: 10000
B10: TIR | D10: =IRR(G11:M11) -> 0.20056308 | F10: Venda | M10: 200000
G11: =SUM(G8:G10) -> -100000 | H11: =SUM(H8:H10) -> 10000 | I11: =SUM(I8:I10) -> 10000 | J11: =SUM(J8:J10) -> 10000 | K11: =SUM(K8:K10) -> 10000 | L11: =SUM(L8:L10) -> 10000 | M11: =SUM(M8:M10) -> 210000
B15: Ex 2.0 | C15: Faça Você | D15: Resposta | G15: 2020 | H15: 2021 | I15: 2022 | J15: 2023 | K15: 2025 | L15: 2026 | M15: 2027
B16: Custo de Capital | D16: 0.08 | F16: Investimento | G16: -235000
B17: VPL | D17: {=NPV(D16,H19:M19)+G19} -> -4744.4971 | F17: Renda | H17: 8000 | I17: 9000 | J17: 10000 | K17: 11000 | L17: 12000 | M17: 13000
B18: TIR | D18: =IRR(G19:M19) -> 0.076001586 | F18: Venda | M18: 290000
G19: =SUM(G16:G18) -> -235000 | H19: =SUM(H16:H18) -> 8000 | I19: =SUM(I16:I18) -> 9000 | J19: =SUM(J16:J18) -> 10000 | K19: =SUM(K16:K18) -> 11000 | L19: =SUM(L16:L18) -> 12000 | M19: =SUM(M16:M18) -> 303000
B23: Ex 2.0 | C23: Faça Você | D23: Resposta | G23: 2020 | H23: 2021 | I23: 2022 | J23: 2023 | K23: 2025 | L23: 2026 | M23: 2027
B24: Custo de Capital | D24: 0.095 | F24: Investimento | G24: -90000
B25: VPL | D25: {=NPV(D24,H27:M27)+G27} -> 7519.4105 | F25: Renda | H25: 5000 | I25: 5500 | J25: 6000 | K25: 8000 | L25: 9000 | M25: 10000
B26: TIR | D26: =IRR(G27:M27) -> 0.11187053 | F26: Venda | M26: 115000
G27: =SUM(G24:G26) -> -90000 | H27: =SUM(H24:H26) -> 5000 | I27: =SUM(I24:I26) -> 5500 | J27: =SUM(J24:J26) -> 6000 | K27: =SUM(K24:K26) -> 8000 | L27: =SUM(L24:L26) -> 9000 | M27: =SUM(M24:M26) -> 125000

Sheet 03.1-TIRxVPL
B1: © Escola de Imóveis - www.escoladeimoveis.com.br | Siga no instagram e tenha o melhor conteúdo: @escoladeimoveis
B2: É terminantemente proibida a utilização, acesso, cópia ou divulgação não autorizada das informações presentes nesta planilha.
B3: ATENÇÃO: SOMENTE ALTERAR AS CÉLULAS ROXAS COM A ESCRITA FAÇA VOCÊ
B5: Diferença TIR e VPL
B7: Ex 1.0 | C7: Resposta | F7: 2020 | G7: 2021 | H7: 2022 | I7: 2023 | J7: 2025 | K7: 2026 | L7: 2027
B8: Custo de Capital | C8: 0.06 | E8: Investimento | F8: -50000
B9: VPL | C9: {=NPV(C8,G11:L11)+F11} -> 73599.829 | E9: Renda | G9: 25000 | H9: 0 | I9: 5000 | J9: 5000 | K9: 5000 | L9: 0
B10: TIR | C10: =IRR(F11:L11) -> 0.30336361 | E10: Venda | L10: 125000
B11: Receita Total | C11: =SUM(G11:L11) -> 165000 | F11: =SUM(F8:F10) -> -50000 | G11: =SUM(G8:G10) -> 25000 | H11: =SUM(H8:H10) -> 0 | I11: =SUM(I8:I10) -> 5000 | J11: =SUM(J8:J10) -> 5000 | K11: =SUM(K8:K10) -> 5000 | L11: =SUM(L8:L10) -> 125000
B15: Ex 2.0 | C15: Resposta | F15: 2020 | G15: 2021 | H15: 2022 | I15: 2023 | J15: 2025 | K15: 2026 | L15: 2027
B16: Custo de Capital | C16: 0.06 | E16: Investimento | F16: -50000
B17: VPL | C17: {=NPV(C16,G19:L19)+F19} -> 67203.271 | E17: Renda | G17: 0 | H17: 0 | I17: 5000 | J17: 0 | K17: 5000 | L17: 0
B18: TIR | C18: =IRR(F19:L19) -> 0.22668805 | E18: Venda | L18: 155000
B19: Receita Total | C19: =SUM(G19:L19) -> 165000 | F19: =SUM(F16:F18) -> -50000 | G19: =SUM(G16:G18) -> 0 | H19: =SUM(H16:H18) -> 0 | I19: =SUM(I16:I18) -> 5000 | J19: =SUM(J16:J18) -> 0 | K19: =SUM(K16:K18) -> 5000 | L19: =SUM(L16:L18) -> 155000
B23: Ex 3.0 | C23: Resposta | F23: 2020 | G23: 2021 | H23: 2022 | I23: 2023 | J23: 2025 | K23: 2026 | L23: 2027
B24: Custo de Capital | C24: 0.06 | E24: Investimento | F24: -20000
B25: VPL | C25: {=NPV(C24,G27:L27)+F27} -> 27338.1 | E25: Renda | G25: 0 | H25: 0 | I25: 0 | J25: 0 | K25: 0 | L25: 0
B26: TIR | C26: =IRR(F27:L27) -> 0.22368416 | E26: Venda | L26: 67150
B27: Receita Total | C27: =SUM(G27:L27) -> 67150 | F27: =SUM(F24:F26) -> -20000 | G27: =SUM(G24:G26) -> 0 | H27: =SUM(H24:H26) -> 0 | I27: =SUM(I24:I26) -> 0 | J27: =SUM(J24:J26) -> 0 | K27: =SUM(K24:K26) -> 0 | L27: =SUM(L24:L26) -> 67150
B31: Ex 4.0 | C31: Resposta | F31: 2020 | G31: 2021 | H31: 2022 | I31: 2023 | J31: 2025 | K31: 2026 | L31: 2027
B32: Custo de Capital | C32: 0.06 | E32: Investimento | F32: -20000
B33: VPL | C33: {=NPV(C32,G35:L35)+F35} -> 17293.311 | E33: Renda | G33: 4000 | H33: 4000 | I33: 4000 | J33: 4000 | K33: 4000 | L33: 4000
B34: TIR | C34: =IRR(F35:L35) -> 0.22371844 | E34: Venda | L34: 25000
B35: Receita Total | C35: =SUM(G35:L35) -> 49000 | F35: =SUM(F32:F34) -> -20000 | G35: =SUM(G32:G34) -> 4000 | H35: =SUM(H32:H34) -> 4000 | I35: =SUM(I32:I34) -> 4000 | J35: =SUM(J32:J34) -> 4000 | K35: =SUM(K32:K34) -> 4000 | L35: =SUM(L32:L34) -> 29000

Sheet 04-ROI
B1: © Escola de Imóveis - www.escoladeimoveis.com.br | Siga no instagram e tenha o melhor conteúdo: @escoladeimoveis
B2: É terminantemente proibida a utilização, acesso, cópia ou divulgação não autorizada das informações presentes nesta planilha.
B3: ATENÇÃO: SOMENTE ALTERAR AS CÉLULAS ROXAS COM A ESCRITA FAÇA VOCÊ
B5: Retorno sobre o Investimento (ROI) e Múltiplo
B7: Ex 1.0 | C7: Faça Você | D7: Resposta | G7: 2020 | H7: 2021 | I7: 2022 | J7: 2023 | K7: 2025 | L7: 2026 | M7: 2027
B8: Custo de Capital | D8: 0.06 | F8: Investimento | G8: -100000
B9: VPL | D9: {=NPV(D8,H11:M11)+G11} -> 90165.351 | F9: Renda | H9: 10000 | I9: 10000 | J9: 10000 | K9: 10000 | L9: 10000 | M9: 10000
B10: TIR | D10: =IRR(G11:M11) -> 0.20056308 | F10: Venda | M10: 200000
B11: ROI | D11: =(SUM(H11:M11)+G11)/-G11 -> 1.6 | G11: =SUM(G8:G10) -> -100000 | H11: =SUM(H8:H10) -> 10000 | I11: =SUM(I8:I10) -> 10000 | J11: =SUM(J8:J10) -> 10000 | K11: =SUM(K8:K10) -> 10000 | L11: =SUM(L8:L10) -> 10000 | M11: =SUM(M8:M10) -> 210000
B12: Múltiplo | D12: =SUM(H11:M11)/-G11 -> 2.6
B15: Ex 2.0 | C15: Faça Você | D15: Resposta | G15: 2020 | H15: 2021 | I15: 2022 | J15: 2023 | K15: 2025 | L15: 2026 | M15: 2027
B16: Custo de Capital | D16: 0.08 | F16: Investimento | G16: -235000
B17: VPL | D17: {=NPV(D16,H19:M19)+G19} -> -4744.4971 | F17: Renda | H17: 8000 | I17: 9000 | J17: 10000 | K17: 11000 | L17: 12000 | M17: 13000
B18: TIR | D18: =IRR(G19:M19) -> 0.076001586 | F18: Venda | M18: 290000
B19: ROI | D19: =(SUM(H19:M19)+G19)/-G19 -> 0.50212766 | G19: =SUM(G16:G18) -> -235000 | H19: =SUM(H16:H18) -> 8000 | I19: =SUM(I16:I18) -> 9000 | J19: =SUM(J16:J18) -> 10000 | K19: =SUM(K16:K18) -> 11000 | L19: =SUM(L16:L18) -> 12000 | M19: =SUM(M16:M18) -> 303000
B20: Múltiplo | D20: =SUM(H19:M19)/-G19 -> 1.5021277
B23: Ex 2.0 | C23: Faça Você | D23: Resposta | G23: 2020 | H23: 2021 | I23: 2022 | J23: 2023 | K23: 2025 | L23: 2026 | M23: 2027
B24: Custo de Capital | D24: 0.095 | F24: Investimento | G24: -90000
B25: VPL | D25: {=NPV(D24,H27:M27)+G27} -> 7519.4105 | F25: Renda | H25: 5000 | I25: 5500 | J25: 6000 | K25: 8000 | L25: 9000 | M25: 10000
B26: TIR | D26: =IRR(G27:M27) -> 0.11187053 | F26: Venda | M26: 115000
B27: ROI | D27: =(SUM(H27:M27)+G27)/-G27 -> 0.76111111 | G27: =SUM(G24:G26) -> -90000 | H27: =SUM(H24:H26) -> 5000 | I27: =SUM(I24:I26) -> 5500 | J27: =SUM(J24:J26) -> 6000 | K27: =SUM(K24:K26) -> 8000 | L27: =SUM(L24:L26) -> 9000 | M27: =SUM(M24:M26) -> 125000
B28: Múltiplo | D28: =SUM(H27:M27)/-G27 -> 1.7611111

Sheet 05-Payback
B1: © Escola de Imóveis - www.escoladeimoveis.com.br | Siga no instagram e tenha o melhor conteúdo: @escoladeimoveis
B2: É terminantemente proibida a utilização, acesso, cópia ou divulgação não autorizada das informações presentes nesta planilha.
B3: ATENÇÃO: SOMENTE ALTERAR AS CÉLULAS ROXAS COM A ESCRITA FAÇA VOCÊ
B5: Payback
B7: Ex 1.0 | C7: Faça Você | D7: Resposta | G7: 2020 | H7: 2021 | I7: 2022 | J7: 2023 | K7: 2025 | L7: 2026 | M7: 2027
B8: Payback 1 | D8: 4 | F8: Investimento | G8: -100000
F9: Renda | H9: 25000 | I9: 25000 | J9: 25000 | K9: 25000 | L9: 0 | M9: 0
F10: Venda | M10: 200000
G11: =SUM(G8:G10) -> -100000 | H11: =SUM(H8:H10) -> 25000 | I11: =SUM(I8:I10) -> 25000 | J11: =SUM(J8:J10) -> 25000 | K11: =SUM(K8:K10) -> 25000 | L11: =SUM(L8:L10) -> 0 | M11: =SUM(M8:M10) -> 200000
F12: Payback Saldo | H12: =G11+H11 -> -75000 | I12: =H12+I11 -> -50000 | J12: =I12+J11 -> -25000 | K12: =J12+K11 -> 0 | L12: =K12+L11 -> 0
G13: 0 | H13: 1 | I13: 2 | J13: 3 | K13: 4 | L13: 5
B16: Ex 2.0 | C16: Faça Você | D16: Resposta | G16: 2020 | H16: 2021 | I16: 2022 | J16: 2023 | K16: 2025 | L16: 2026 | M16: 2027
B17: Payback | D17: =J22+(-J21/K20) -> 3.3333333 | F17: Investimento | G17: -60000
F18: Renda | H18: 20000 | I18: 20000 | J18: 15000 | K18: 15000 | L18: 15000 | M18: 15000
F19: Venda | M19: 80000
G20: =SUM(G17:G19) -> -60000 | H20: =SUM(H17:H19) -> 20000 | I20: =SUM(I17:I19) -> 20000 | J20: =SUM(J17:J19) -> 15000 | K20: =SUM(K17:K19) -> 15000 | L20: =SUM(L17:L19) -> 15000 | M20: =SUM(M17:M19) -> 95000
F21: Payback Saldo | H21: =G20+H20 -> -40000 | I21: =H21+I20 -> -20000 | J21: =I21+J20 -> -5000 | K21: =J21+K20 -> 10000 | L21: =K21+L20 -> 25000
G22: 0 | H22: 1 | I22: 2 | J22: 3 | K22: 4 | L22: 5
B25: Ex 3.0 | C25: Faça Você | D25: Resposta | G25: 2020 | H25: 2021 | I25: 2022 | J25: 2023 | K25: 2025 | L25: 2026 | M25: 2027
B26: Payback | D26: =K31+(-K30/L29) -> 4.2857143 | F26: Investimento | G26: -90000
F27: Renda | H27: 16000 | I27: 16000 | J27: 24000 | K27: 26000 | L27: 28000 | M27: 10000
F28: Venda | M28: 115000
G29: =SUM(G26:G28) -> -90000 | H29: =SUM(H26:H28) -> 16000 | I29: =SUM(I26:I28) -> 16000 | J29: =SUM(J26:J28) -> 24000 | K29: =SUM(K26:K28) -> 26000 | L29: =SUM(L26:L28) -> 28000 | M29: =SUM(M26:M28) -> 125000
F30: Payback Saldo | H30: =G29+H29 -> -74000 | I30: =H30+I29 -> -58000 | J30: =I30+J29 -> -34000 | K30: =J30+K29 -> -8000 | L30: =K30+L29 -> 20000
G31: 0 | H31: 1 | I31: 2 | J31: 3 | K31: 4 | L31: 5

Sheet 06-CAPYield
B1: © Escola de Imóveis - www.escoladeimoveis.com.br | Siga no instagram e tenha o melhor conteúdo: @escoladeimoveis
B2: É terminantemente proibida a utilização, acesso, cópia ou divulgação não autorizada das informações presentes nesta planilha.
B3: ATENÇÃO: SOMENTE ALTERAR AS CÉLULAS ROXAS COM A ESCRITA FAÇA VOCÊ
B5: CAP & Yield
B7: Ex 1.0 | C7: Faça Você | D7: Resposta | G7: 2020 | H7: 2021 | I7: 2022 | J7: 2023 | K7: 2025 | L7: 2026 | M7: 2027
B8: CAP 2021 | D8: =H10/-G8 -> 0.1 | F8: À Vista | G8: -100000
B9: Yield 2021 Ala | D9: =(H10-H11)/-G9 -> 0.06 | F9: Alavancado | G9: -50000
B10: Yield Médio Ala | D10: =AVERAGE(G14:M14) -> 0.1 | F10: Renda | G10: 10000 | H10: 10000 | I10: 10000 | J10: 10000 | K10: 10000 | L10: 10000 | M10: 10000
F11: Financiamento | G11: 8000 | H11: 7000 | I11: 6000 | J11: 5000 | K11: 4000 | L11: 3000 | M11: 2000
F13: Cap Rate | G13: =G10/(-$G$8) -> 0.1 | H13: =H10/(-$G$8) -> 0.1 | I13: =I10/(-$G$8) -> 0.1 | J13: =J10/(-$G$8) -> 0.1 | K13: =K10/(-$G$8) -> 0.1 | L13: =L10/(-$G$8) -> 0.1 | M13: =M10/(-$G$8) -> 0.1
F14: Yield Ala | G14: =(G10-G11)/-$G$9 -> 0.04 | H14: =(H10-H11)/-$G$9 -> 0.06 | I14: =(I10-I11)/-$G$9 -> 0.08 | J14: =(J10-J11)/-$G$9 -> 0.1 | K14: =(K10-K11)/-$G$9 -> 0.12 | L14: =(L10-L11)/-$G$9 -> 0.14 | M14: =(M10-M11)/-$G$9 -> 0.16
B17: Ex 2.0 | C17: Faça Você | D17: Resposta | G17: 2020 | H17: 2021 | I17: 2022 | J17: 2023 | K17: 2025 | L17: 2026 | M17: 2027
B18: CAP 2021 | D18: =H20/-G18 -> 0.053333333 | F18: À Vista | G18: -150000
B19: Yield 2021 Ala | D19: =(H20-H21)/-G19 -> 0.025 | F19: Alavancado | G19: -100000
B20: Yield Médio Ala | D20: =AVERAGE(G24:M24) -> 0.056428571 | F20: Renda | G20: 8000 | H20: 8000 | I20: 9000 | J20: 10000 | K20: 11000 | L20: 12000 | M20: 13000
F21: Financiamento | G21: 6000 | H21: 5500 | I21: 5000 | J21: 4500 | K21: 4000 | L21: 3500 | M21: 3000
F23: Cap Rate | G23: =G20/(-$G$18) -> 0.053333333 | H23: =H20/(-$G$18) -> 0.053333333 | I23: =I20/(-$G$18) -> 0.06 | J23: =J20/(-$G$18) -> 0.066666667 | K23: =K20/(-$G$18) -> 0.073333333 | L23: =L20/(-$G$18) -> 0.08 | M23: =M20/(-$G$18) -> 0.086666667
F24: Yield Ala | G24: =(G20-G21)/-$G$19 -> 0.02 | H24: =(H20-H21)/-$G$19 -> 0.025 | I24: =(I20-I21)/-$G$19 -> 0.04 | J24: =(J20-J21)/-$G$19 -> 0.055 | K24: =(K20-K21)/-$G$19 -> 0.07 | L24: =(L20-L21)/-$G$19 -> 0.085 | M24: =(M20-M21)/-$G$19 -> 0.1
B27: Ex 2.0 | C27: Faça Você | D27: Resposta | G27: 2020 | H27: 2021 | I27: 2022 | J27: 2023 | K27: 2025 | L27: 2026 | M27: 2027
B28: CAP 2021 | D28: =H30/-G28 -> 0.04137931 | F28: À Vista | G28: -290000
B29: Yield 2021 Ala | D29: =(H30-H31)/-G29 -> 0.12142857 | F29: Alavancado | G29: -70000
B30: Yield Médio Ala | D30: =AVERAGE(G34:M34) -> 0.10510204 | F30: Renda | G30: 12000 | H30: 12000 | I30: 14000 | J30: 13000 | K30: 14000 | L30: 16000 | M30: 17000
F31: Financiamento | G31: 2500 | H31: 3500 | I31: 4500 | J31: 6500 | K31: 8000 | L31: 9500 | M31: 12000
F33: Cap Rate | G33: =G30/(-$G$28) -> 0.04137931 | H33: =H30/(-$G$28) -> 0.04137931 | I33: =I30/(-$G$28) -> 0.048275862 | J33: =J30/(-$G$28) -> 0.044827586 | K33: =K30/(-$G$28) -> 0.048275862 | L33: =L30/(-$G$28) -> 0.055172414 | M33: =M30/(-$G$28) -> 0.05862069
F34: Yield Ala | G34: =(G30-G31)/-$G$29 -> 0.13571429 | H34: =(H30-H31)/-$G$29 -> 0.12142857 | I34: =(I30-I31)/-$G$29 -> 0.13571429 | J34: =(J30-J31)/-$G$29 -> 0.092857143 | K34: =(K30-K31)/-$G$29 -> 0.085714286 | L34: =(L30-L31)/-$G$29 -> 0.092857143 | M34: =(M30-M31)/-$G$29 -> 0.071428571

Sheet 08-SAC
B1: © Escola de Imóveis - www.escoladeimoveis.com.br | Siga no instagram e tenha o melhor conteúdo: @escoladeimoveis
B2: É terminantemente proibida a utilização, acesso, cópia ou divulgação não autorizada das informações presentes nesta planilha.
B3: ATENÇÃO: SOMENTE ALTERAR AS CÉLULAS ROXAS COM A ESCRITA FAÇA VOCÊ
B5: SAC | E5: Faça Você | G5: Faça Você
D6: Valor Imóvel | E6: 200000 | F6: LTV | G6: 0.8 | M6: Juros Devidos | N6: =D431 -> 203592.87
M7: Principal Devido | N7: =F431 -> 160000
B8: Empréstimo | C8: =E6*G6 -> 160000 | D8: Nº Parcelas | E8: 420 | F8: Taxa Anual | G8: 0.075 | H8: Taxa Mensal | I8: =(1+G8)^(1/12)-1 -> 0.006044919 | J8: Renda Min. | K8: =G11/0.3 -> 4493.7981 | M8: Total Devido | N8: =G431 -> 363592.87
B10: Parcela | C10: Saldo Inicial | D10: Juros | E10: Saldo Atualizado | F10: Amortização | G10: Prestação | H10: Saldo Devedor
A11: =IF(AND(E8>0,E8<421),1,0) -> 1 | B11: =IF(A11>0,1,0) -> 1 | C11: =IF(B11>0,C8,0) -> 160000 | D11: =IF(B11>0,C11*$I$8,0) -> 967.18704 | E11: =IF(B11>0,C11+D11,0) -> 160967.19 | F11: =IF($E$8>0,$C$8/$E$8,0) -> 380.95238 | G11: =IF(B11>0,D11+F11,0) -> 1348.1394 | H11: =IF(B11>0,E11-G11,0) -> 159619.05
B12: =IF(AND(B11>0,B11<$E$8),B11+1,0) -> 2 | C12: =IF(B12>0,H11,0) -> 159619.05 | D12: =IF(B12>0,C12*$I$8,0) -> 964.88422 | E12: =IF(B12>0,C12+D12,0) -> 160583.93 | F12: =IF(B12>0,$C$8/$E$8,0) -> 380.95238 | G12: =IF(B12>0,D12+F12,0) -> 1345.8366 | H12: =IF(B12>0,E12-G12,0) -> 159238.1
B13: =IF(AND(B12>0,B12<$E$8),B12+1,0) -> 3 | C13: =IF(B13>0,H12,0) -> 159238.1 | D13: =IF(B13>0,C13*$I$8,0) -> 962.58139 | E13: =IF(B13>0,C13+D13,0) -> 160200.68 | F13: =IF(B13>0,$C$8/$E$8,0) -> 380.95238 | G13: =IF(B13>0,D13+F13,0) -> 1343.5338 | H13: =IF(B13>0,E13-G13,0) -> 158857.14
B14: =IF(AND(B13>0,B13<$E$8),B13+1,0) -> 4 | C14: =IF(B14>0,H13,0) -> 158857.14 | D14: =IF(B14>0,C14*$I$8,0) -> 960.27857 | E14: =IF(B14>0,C14+D14,0) -> 159817.42 | F14: =IF(B14>0,$C$8/$E$8,0) -> 380.95238 | G14: =IF(B14>0,D14+F14,0) -> 1341.2309 | H14: =IF(B14>0,E14-G14,0) -> 158476.19
B15: =IF(AND(B14>0,B14<$E$8),B14+1,0) -> 5 | C15: =IF(B15>0,H14,0) -> 158476.19 | D15: =IF(B15>0,C15*$I$8,0) -> 957.97574 | E15: =IF(B15>0,C15+D15,0) -> 159434.17 | F15: =IF(B15>0,$C$8/$E$8,0) -> 380.95238 | G15: =IF(B15>0,D15+F15,0) -> 1338.9281 | H15: =IF(B15>0,E15-G15,0) -> 158095.24
B16: =IF(AND(B15>0,B15<$E$8),B15+1,0) -> 6 | C16: =IF(B16>0,H15,0) -> 158095.24 | D16: =IF(B16>0,C16*$I$8,0) -> 955.67291 | E16: =IF(B16>0,C16+D16,0) -> 159050.91 | F16: =IF(B16>0,$C$8/$E$8,0) -> 380.95238 | G16: =IF(B16>0,D16+F16,0) -> 1336.6253 | H16: =IF(B16>0,E16-G16,0) -> 157714.29
B17: =IF(AND(B16>0,B16<$E$8),B16+1,0) -> 7 | C17: =IF(B17>0,H16,0) -> 157714.29 | D17: =IF(B17>0,C17*$I$8,0) -> 953.37009 | E17: =IF(B17>0,C17+D17,0) -> 158667.66 | F17: =IF(B17>0,$C$8/$E$8,0) -> 380.95238 | G17: =IF(B17>0,D17+F17,0) -> 1334.3225 | H17: =IF(B17>0,E17-G17,0) -> 157333.33
B18: =IF(AND(B17>0,B17<$E$8),B17+1,0) -> 8 | C18: =IF(B18>0,H17,0) -> 157333.33 | D18: =IF(B18>0,C18*$I$8,0) -> 951.06726 | E18: =IF(B18>0,C18+D18,0) -> 158284.4 | F18: =IF(B18>0,$C$8/$E$8,0) -> 380.95238 | G18: =IF(B18>0,D18+F18,0) -> 1332.0196 | H18: =IF(B18>0,E18-G18,0) -> 156952.38
B19: =IF(AND(B18>0,B18<$E$8),B18+1,0) -> 9 | C19: =IF(B19>0,H18,0) -> 156952.38 | D19: =IF(B19>0,C19*$I$8,0) -> 948.76443 | E19: =IF(B19>0,C19+D19,0) -> 157901.15 | F19: =IF(B19>0,$C$8/$E$8,0) -> 380.95238 | G19: =IF(B19>0,D19+F19,0) -> 1329.7168 | H19: =IF(B19>0,E19-G19,0) -> 156571.43
B20: =IF(AND(B19>0,B19<$E$8),B19+1,0) -> 10 | C20: =IF(B20>0,H19,0) -> 156571.43 | D20: =IF(B20>0,C20*$I$8,0) -> 946.46161 | E20: =IF(B20>0,C20+D20,0) -> 157517.89 | F20: =IF(B20>0,$C$8/$E$8,0) -> 380.95238 | G20: =IF(B20>0,D20+F20,0) -> 1327.414 | H20: =IF(B20>0,E20-G20,0) -> 156190.48
B21: =IF(AND(B20>0,B20<$E$8),B20+1,0) -> 11 | C21: =IF(B21>0,H20,0) -> 156190.48 | D21: =IF(B21>0,C21*$I$8,0) -> 944.15878 | E21: =IF(B21>0,C21+D21,0) -> 157134.63 | F21: =IF(B21>0,$C$8/$E$8,0) -> 380.95238 | G21: =IF(B21>0,D21+F21,0) -> 1325.1112 | H21: =IF(B21>0,E21-G21,0) -> 155809.52
B22: =IF(AND(B21>0,B21<$E$8),B21+1,0) -> 12 | C22: =IF(B22>0,H21,0) -> 155809.52 | D22: =IF(B22>0,C22*$I$8,0) -> 941.85595 | E22: =IF(B22>0,C22+D22,0) -> 156751.38 | F22: =IF(B22>0,$C$8/$E$8,0) -> 380.95238 | G22: =IF(B22>0,D22+F22,0) -> 1322.8083 | H22: =IF(B22>0,E22-G22,0) -> 155428.57
B23: =IF(AND(B22>0,B22<$E$8),B22+1,0) -> 13 | C23: =IF(B23>0,H22,0) -> 155428.57 | D23: =IF(B23>0,C23*$I$8,0) -> 939.55313 | E23: =IF(B23>0,C23+D23,0) -> 156368.12 | F23: =IF(B23>0,$C$8/$E$8,0) -> 380.95238 | G23: =IF(B23>0,D23+F23,0) -> 1320.5055 | H23: =IF(B23>0,E23-G23,0) -> 155047.62
... B430: =IF(AND(B429>0,B429<$E$8),B429+1,0) -> 420 | C430: =IF(B430>0,H429,0) -> 380.95238 | D430: =IF(B430>0,C430*$I$8,0) -> 2.3028263 | E430: =IF(B430>0,C430+D430,0) -> 383.25521 | F430: =IF(B430>0,$C$8/$E$8,0) -> 380.95238 | G430: =IF(B430>0,D430+F430,0) -> 383.25521 | H430: =IF(B430>0,E430-G430,0) -> -9.7998054e-11
D431: =SUM(D11:D430) -> 203592.87 | F431: =SUM(F11:F430) -> 160000 | G431: =SUM(G11:G430) -> 363592.87

Sheet 09-PRICE
B1: © Escola de Imóveis - www.escoladeimoveis.com.br | Siga no instagram e tenha o melhor conteúdo: @escoladeimoveis
B2: É terminantemente proibida a utilização, acesso, cópia ou divulgação não autorizada das informações presentes nesta planilha.
B3: ATENÇÃO: SOMENTE ALTERAR AS CÉLULAS ROXAS COM A ESCRITA FAÇA VOCÊ
B5: PRICE | E5: Faça Você | G5: Faça Você
D6: Valor Imóvel | E6: 200000 | F6: LTV | G6: 0.8 | M6: Juros Devidos | N6: =D431 -> 281331.63
M7: Principal Devido | N7: =F431 -> 160000
B8: Empréstimo | C8: =E6*G6 -> 160000 | D8: Nº Parcelas | E8: 420 | F8: Taxa Anual | G8: 0.075 | H8: Taxa Mensal | I8: =(1+G8)^(1/12)-1 -> 0.006044919 | J8: Renda Min. | K8: =G11/0.3 -> 3502.632 | M8: Total Devido | N8: =G431 -> 441331.63
B10: Parcela | C10: Saldo Inicial | D10: Juros | E10: Saldo Atualizado | F10: Amortização | G10: Prestação | H10: Saldo Devedor
A11: =IF(AND(E8>0,E8<421),1,0) -> 1 | B11: =IF(A11>0,1,0) -> 1 | C11: =IF(B11>0,C8,0) -> 160000 | D11: =IF(B11>0,C11*$I$8,0) -> 967.18704 | E11: =IF(B11>0,C11+D11,0) -> 160967.19 | F11: =IF($E$8>0,G11-D11,0) -> 83.602548 | G11: =IF(B11>0,-PMT($I$8,$E$8,$C$8),0) -> 1050.7896 | H11: =IF(B11>0,E11-G11,0) -> 159916.4
B12: =IF(AND(B11>0,B11<$E$8),B11+1,0) -> 2 | C12: =IF(B12>0,H11,0) -> 159916.4 | D12: =IF(B12>0,C12*$I$8,0) -> 966.68167 | E12: =IF(B12>0,C12+D12,0) -> 160883.08 | F12: =IF($E$8>0,G12-D12,0) -> 84.107919 | G12: =IF(B12>0,G11,0) -> 1050.7896 | H12: =IF(B12>0,E12-G12,0) -> 159832.29
B13: =IF(AND(B12>0,B12<$E$8),B12+1,0) -> 3 | C13: =IF(B13>0,H12,0) -> 159832.29 | D13: =IF(B13>0,C13*$I$8,0) -> 966.17325 | E13: =IF(B13>0,C13+D13,0) -> 160798.46 | F13: =IF($E$8>0,G13-D13,0) -> 84.616344 | G13: =IF(B13>0,G12,0) -> 1050.7896 | H13: =IF(B13>0,E13-G13,0) -> 159747.67
B14: =IF(AND(B13>0,B13<$E$8),B13+1,0) -> 4 | C14: =IF(B14>0,H13,0) -> 159747.67 | D14: =IF(B14>0,C14*$I$8,0) -> 965.66175 | E14: =IF(B14>0,C14+D14,0) -> 160713.33 | F14: =IF($E$8>0,G14-D14,0) -> 85.127843 | G14: =IF(B14>0,G13,0) -> 1050.7896 | H14: =IF(B14>0,E14-G14,0) -> 159662.55
B15: =IF(AND(B14>0,B14<$E$8),B14+1,0) -> 5 | C15: =IF(B15>0,H14,0) -> 159662.55 | D15: =IF(B15>0,C15*$I$8,0) -> 965.14716 | E15: =IF(B15>0,C15+D15,0) -> 160627.69 | F15: =IF($E$8>0,G15-D15,0) -> 85.642434 | G15: =IF(B15>0,G14,0) -> 1050.7896 | H15: =IF(B15>0,E15-G15,0) -> 159576.9
B16: =IF(AND(B15>0,B15<$E$8),B15+1,0) -> 6 | C16: =IF(B16>0,H15,0) -> 159576.9 | D16: =IF(B16>0,C16*$I$8,0) -> 964.62946 | E16: =IF(B16>0,C16+D16,0) -> 160541.53 | F16: =IF($E$8>0,G16-D16,0) -> 86.160136 | G16: =IF(B16>0,G15,0) -> 1050.7896 | H16: =IF(B16>0,E16-G16,0) -> 159490.74
B17: =IF(AND(B16>0,B16<$E$8),B16+1,0) -> 7 | C17: =IF(B17>0,H16,0) -> 159490.74 | D17: =IF(B17>0,C17*$I$8,0) -> 964.10863 | E17: =IF(B17>0,C17+D17,0) -> 160454.85 | F17: =IF($E$8>0,G17-D17,0) -> 86.680967 | G17: =IF(B17>0,G16,0) -> 1050.7896 | H17: =IF(B17>0,E17-G17,0) -> 159404.06
B18: =IF(AND(B17>0,B17<$E$8),B17+1,0) -> 8 | C18: =IF(B18>0,H17,0) -> 159404.06 | D18: =IF(B18>0,C18*$I$8,0) -> 963.58465 | E18: =IF(B18>0,C18+D18,0) -> 160367.65 | F18: =IF($E$8>0,G18-D18,0) -> 87.204946 | G18: =IF(B18>0,G17,0) -> 1050.7896 | H18: =IF(B18>0,E18-G18,0) -> 159316.86
B19: =IF(AND(B18>0,B18<$E$8),B18+1,0) -> 9 | C19: =IF(B19>0,H18,0) -> 159316.86 | D19: =IF(B19>0,C19*$I$8,0) -> 963.0575 | E19: =IF(B19>0,C19+D19,0) -> 160279.91 | F19: =IF($E$8>0,G19-D19,0) -> 87.732093 | G19: =IF(B19>0,G18,0) -> 1050.7896 | H19: =IF(B19>0,E19-G19,0) -> 159229.12
B20: =IF(AND(B19>0,B19<$E$8),B19+1,0) -> 10 | C20: =IF(B20>0,H19,0) -> 159229.12 | D20: =IF(B20>0,C20*$I$8,0) -> 962.52717 | E20: =IF(B20>0,C20+D20,0) -> 160191.65 | F20: =IF($E$8>0,G20-D20,0) -> 88.262426 | G20: =IF(B20>0,G19,0) -> 1050.7896 | H20: =IF(B20>0,E20-G20,0) -> 159140.86
B21: =IF(AND(B20>0,B20<$E$8),B20+1,0) -> 11 | C21: =IF(B21>0,H20,0) -> 159140.86 | D21: =IF(B21>0,C21*$I$8,0) -> 961.99363 | E21: =IF(B21>0,C21+D21,0) -> 160102.86 | F21: =IF($E$8>0,G21-D21,0) -> 88.795966 | G21: =IF(B21>0,G20,0) -> 1050.7896 | H21: =IF(B21>0,E21-G21,0) -> 159052.07
B22: =IF(AND(B21>0,B21<$E$8),B21+1,0) -> 12 | C22: =IF(B22>0,H21,0) -> 159052.07 | D22: =IF(B22>0,C22*$I$8,0) -> 961.45686 | E22: =IF(B22>0,C22+D22,0) -> 160013.52 | F22: =IF($E$8>0,G22-D22,0) -> 89.33273 | G22: =IF(B22>0,G21,0) -> 1050.7896 | H22: =IF(B22>0,E22-G22,0) -> 158962.73
B23: =IF(AND(B22>0,B22<$E$8),B22+1,0) -> 13 | C23: =IF(B23>0,H22,0) -> 158962.73 | D23: =IF(B23>0,C23*$I$8,0) -> 960.91685 | E23: =IF(B23>0,C23+D23,0) -> 159923.65 | F23: =IF($E$8>0,G23-D23,0) -> 89.872739 | G23: =IF(B23>0,G22,0) -> 1050.7896 | H23: =IF(B23>0,E23-G23,0) -> 158872.86
... B430: =IF(AND(B429>0,B429<$E$8),B429+1,0) -> 420 | C430: =IF(B430>0,H429,0) -> 1044.4758 | D430: =IF(B430>0,C430*$I$8,0) -> 6.3137718 | E430: =IF(B430>0,C430+D430,0) -> 1050.7896 | F430: =IF($E$8>0,G430-D430,0) -> 1044.4758 | G430: =IF(B430>0,G429,0) -> 1050.7896 | H430: =IF(B430>0,E430-G430,0) -> -4.7866706e-09
D431: =SUM(D11:D430) -> 281331.63 | F431: =SUM(F11:F430) -> 160000 | G431: =SUM(G11:G430) -> 441331.63

Sheet 10-Pesquisa Compra
B1: © Escola de Imóveis - www.escoladeimoveis.com.br | Siga no instagram e tenha o melhor conteúdo: @escoladeimoveis
B2: É terminantemente proibida a utilização, acesso, cópia ou divulgação não autorizada das informações presentes nesta planilha.
B3: ATENÇÃO: SOMENTE ALTERAR AS CÉLULAS ROXAS COM A ESCRITA FAÇA VOCÊ
B5: Pesquisa de Mercado Compra
C7: Faça Você | E7: Faça Você | G7: FI | H7: Faça Você | K7: Faça Você | T7: *Ajustar o custo do piso de acordo com o tamanho médio das comparações
B8: Custo Médio | C8: =AVERAGE(AV:AV) -> 309007.5 | D8: M² Médio | E8: =AVERAGE(AT:AT) -> 9633.547 | F8: FIPEZAP - São Paulo | H8: 9242 | I8: SECOVI - Novos República | K8: 9784.16 | T8: Estimativa Custo Adicional Studio
T9: =100*R12 -> 2600 | U9: 4500 | V9: 500 | W9: 1500 | X9: 500 | Y9: 2500 | Z9: 8000 | AA9: 1000 | AB9: 1000 | AC9: 1000
B10: Endereço | H10: Configuração do Apartamento | T10: Características do Apartamento | AD10: Característicad do Condomínio | AM10: Características Financeiras do Imóvel
B11: Av/Rua | C11: Número | D11: Bairro | E11: Metrô | F11: Condomínio | G11: Link | H11: Dormitórios | I11: Banheiros | J11: Suíte | K11: Vaga | L11: Andar | M11: Posição | N11: Vista | O11: Visual | P11: Aspecto | Q11: Ano | R11: M² Privativo | S11: Parede | T11: Piso | U11: Sacada | V11: Box | W11: Chuveiro | X11: Persiana | Y11: Ar Condicionado | Z11: Mar. Cozinha | AA11: Mar. Banheiro | AB11: Mar. Quarto | AC11: Cooktop | AD11: Portaria | AE11: Lavanderia | AF11: Academia | AG11: Salão de Festas | AH11: Coworking | AI11: Piscina | AJ11: Pet Place | AK11: Bicicletário | AL11: Rooftop | AM11: Condomínio | AN11: Cond/M² | AO11: IPTU Mês | AP11: Compra | AQ11: Cartório | AR11: M² Compra | AS11: Adicional | AT11: M² Total | AU11: Var M² Total | AV11: Custo Total
A12: 1 | B12: Av Duque de Caxias | C12: 61 | D12: Centro | E12: 100m | F12: Smart Santa Cecília | H12: 0 | I12: 1 | J12: 0 | K12: 0 | L12: 4 | M12: Norte | N12: Lateral | O12: Livre | P12: Decorado | Q12: 2018 | R12: 26 | S12: Drywall | T12: Porcelanato | U12: Aberta | V12: Vidro | W12: Gás Individual | X12: Interna | Y12: Quarto/Sala | Z12: Sim | AA12: Sim | AB12: Sim | AC12: Não tem | AD12: 24h | AE12: Industrial | AF12: Simples | AG12: Gourmet | AH12: Pequeno | AI12: Externa | AJ12: Sim | AK12: Com bicicletas | AL12: Sim | AM12: 308 | AN12: =IF(R12<>0,AM12/R12,"") -> 11.846154 | AO12: 55 | AP12: 273000 | AQ12: =IF(R12<>0,5.5%*AP12,"") -> 15015 | AR12: =IFERROR(AP12/R12,"") -> 10500 | AS12: =IF(AC12="Não tem",$AC$9)+IF(AB12="Não tem",$AB$9)+IF(AA12="Não tem",$AA$9)+IF(Z12="Não tem",$Z$9)+IF(Y12="Não tem",$Y$9)+IF(X12="Não tem",$X$9)+IF(W12="Não tem",$W$9)+IF(V12="Não tem",$V$9)+IF(U12="Aberta",$U$9)+IF(T12="Contrapiso",$T$9) -> 5500 | AT12: =IF(R12<>0,(AP12+AS12)/R12,0) -> 10711.538 | AU12: =IF(R12<>0,(AT12/AVERAGE(AT:AT))-100%,"") -> 0.11189974 | AV12: =IF(R12<>0,AP12+AQ12+AS12,0) -> 293515
A13: 2 | B13: Rua dos Timbiras | C13: 395 | D13: Centro | E13: 500m | F13: SP New Home | G13: https://www.quintoandar.com.br/imovel/893047060/comprar?search_rank=%7B%22sortMode%22%3A%22relevance%22%2C%22searchMode%22%3A%22list%22%2C%22resultsOrigin%22%3A%22search%22%2C%22rank%22%3A23%2C%22personalization%22%3Atrue%7D&search_id=%22fa0112d01cae11ebaa36ea959c5fd97d%22&from_route=%22search_results%22 | H13: 1 | I13: 1 | J13: 1 | K13: 1 | L13: 10 | M13: Oeste | N13: Frente | O13: Livre | P13: Novo | Q13: 2017 | R13: 36 | S13: Drywall | T13: Porcelanato | U13: Aberta | V13: Vidro | W13: Gás Individual | X13: Embutida Janela | Y13: Não tem | Z13: Sim | AA13: Sim | AB13: Sim | AC13: Não tem | AD13: 24h | AE13: Industrial | AF13: Completa | AG13: Churrasqueira | AH13: Não tem | AI13: Interna | AJ13: Não tem | AK13: Não tem | AL13: Não tem | AM13: 520 | AN13: =IF(R13<>0,AM13/R13,"") -> 14.444444 | AO13: 84 | AP13: 300000 | AQ13: =IF(R13<>0,5.5%*AP13,"") -> 16500 | AR13: =IFERROR(AP13/R13,"") -> 8333.3333 | AS13: =IF(AC13="Não tem",$AC$9)+IF(AB13="Não tem",$AB$9)+IF(AA13="Não tem",$AA$9)+IF(Z13="Não tem",$Z$9)+IF(Y13="Não tem",$Y$9)+IF(X13="Não tem",$X$9)+IF(W13="Não tem",$W$9)+IF(V13="Não tem",$V$9)+IF(U13="Aberta",$U$9)+IF(T13="Contrapiso",$T$9) -> 8000 | AT13: =IF(R13<>0,(AP13+AS13)/R13,"") -> 8555.5556 | AU13: =IF(R13<>0,(AT13/AVERAGE(AT:AT))-100%,"") -> -0.11189974 | AV13: =IF(R13<>0,AP13+AQ13+AS13,"") -> 324500
A14: 3 | AN14: =IF(R14<>0,AM14/R14,"") | AQ14: =IF(R14<>0,5.5%*AP14,"") | AR14: =IFERROR(AP14/R14,"") | AS14: =IF(AC14="Não tem",$AC$9)+IF(AB14="Não tem",$AB$9)+IF(AA14="Não tem",$AA$9)+IF(Z14="Não tem",$Z$9)+IF(Y14="Não tem",$Y$9)+IF(X14="Não tem",$X$9)+IF(W14="Não tem",$W$9)+IF(V14="Não tem",$V$9)+IF(U14="Aberta",$U$9)+IF(T14="Contrapiso",$T$9) -> 0 | AT14: =IF(R14<>0,(AP14+AS14)/R14,"") | AU14: =IF(R14<>0,(AT14/AVERAGE(AT:AT))-100%,"") | AV14: =IF(R14<>0,AP14+AQ14+AS14,"")
A15: 4 | AN15: =IF(R15<>0,AM15/R15,"") | AQ15: =IF(R15<>0,5.5%*AP15,"") | AR15: =IFERROR(AP15/R15,"") | AS15: =IF(AC15="Não tem",$AC$9)+IF(AB15="Não tem",$AB$9)+IF(AA15="Não tem",$AA$9)+IF(Z15="Não tem",$Z$9)+IF(Y15="Não tem",$Y$9)+IF(X15="Não tem",$X$9)+IF(W15="Não tem",$W$9)+IF(V15="Não tem",$V$9)+IF(U15="Aberta",$U$9)+IF(T15="Contrapiso",$T$9) -> 0 | AT15: =IF(R15<>0,(AP15+AS15)/R15,"") | AU15: =IF(R15<>0,(AT15/AVERAGE(AT:AT))-100%,"") | AV15: =IF(R15<>0,AP15+AQ15+AS15,"")
A16: 5 | AN16: =IF(R16<>0,AM16/R16,"") | AQ16: =IF(R16<>0,5.5%*AP16,"") | AR16: =IFERROR(AP16/R16,"") | AS16: =IF(AC16="Não tem",$AC$9)+IF(AB16="Não tem",$AB$9)+IF(AA16="Não tem",$AA$9)+IF(Z16="Não tem",$Z$9)+IF(Y16="Não tem",$Y$9)+IF(X16="Não tem",$X$9)+IF(W16="Não tem",$W$9)+IF(V16="Não tem",$V$9)+IF(U16="Aberta",$U$9)+IF(T16="Contrapiso",$T$9) -> 0 | AT16: =IF(R16<>0,(AP16+AS16)/R16,"") | AU16: =IF(R16<>0,(AT16/AVERAGE(AT:AT))-100%,"") | AV16: =IF(R16<>0,AP16+AQ16+AS16,"")
A17: 6 | AN17: =IF(R17<>0,AM17/R17,"") | AQ17: =IF(R17<>0,5.5%*AP17,"") | AR17: =IFERROR(AP17/R17,"") | AS17: =IF(AC17="Não tem",$AC$9)+IF(AB17="Não tem",$AB$9)+IF(AA17="Não tem",$AA$9)+IF(Z17="Não tem",$Z$9)+IF(Y17="Não tem",$Y$9)+IF(X17="Não tem",$X$9)+IF(W17="Não tem",$W$9)+IF(V17="Não tem",$V$9)+IF(U17="Aberta",$U$9)+IF(T17="Contrapiso",$T$9) -> 0 | AT17: =IF(R17<>0,(AP17+AS17)/R17,"") | AU17: =IF(R17<>0,(AT17/AVERAGE(AT:AT))-100%,"") | AV17: =IF(R17<>0,AP17+AQ17+AS17,"")
A18: 7 | AN18: =IF(R18<>0,AM18/R18,"") | AQ18: =IF(R18<>0,5.5%*AP18,"") | AR18: =IFERROR(AP18/R18,"") | AS18: =IF(AC18="Não tem",$AC$9)+IF(AB18="Não tem",$AB$9)+IF(AA18="Não tem",$AA$9)+IF(Z18="Não tem",$Z$9)+IF(Y18="Não tem",$Y$9)+IF(X18="Não tem",$X$9)+IF(W18="Não tem",$W$9)+IF(V18="Não tem",$V$9)+IF(U18="Aberta",$U$9)+IF(T18="Contrapiso",$T$9) -> 0 | AT18: =IF(R18<>0,(AP18+AS18)/R18,"") | AU18: =IF(R18<>0,(AT18/AVERAGE(AT:AT))-100%,"") | AV18: =IF(R18<>0,AP18+AQ18+AS18,"")
A19: 8 | AN19: =IF(R19<>0,AM19/R19,"") | AQ19: =IF(R19<>0,5.5%*AP19,"") | AR19: =IFERROR(AP19/R19,"") | AS19: =IF(AC19="Não tem",$AC$9)+IF(AB19="Não tem",$AB$9)+IF(AA19="Não tem",$AA$9)+IF(Z19="Não tem",$Z$9)+IF(Y19="Não tem",$Y$9)+IF(X19="Não tem",$X$9)+IF(W19="Não tem",$W$9)+IF(V19="Não tem",$V$9)+IF(U19="Aberta",$U$9)+IF(T19="Contrapiso",$T$9) -> 0 | AT19: =IF(R19<>0,(AP19+AS19)/R19,"") | AU19: =IF(R19<>0,(AT19/AVERAGE(AT:AT))-100%,"") | AV19: =IF(R19<>0,AP19+AQ19+AS19,"")
A20: 9 | AN20: =IF(R20<>0,AM20/R20,"") | AQ20: =IF(R20<>0,5.5%*AP20,"") | AR20: =IFERROR(AP20/R20,"") | AS20: =IF(AC20="Não tem",$AC$9)+IF(AB20="Não tem",$AB$9)+IF(AA20="Não tem",$AA$9)+IF(Z20="Não tem",$Z$9)+IF(Y20="Não tem",$Y$9)+IF(X20="Não tem",$X$9)+IF(W20="Não tem",$W$9)+IF(V20="Não tem",$V$9)+IF(U20="Aberta",$U$9)+IF(T20="Contrapiso",$T$9) -> 0 | AT20: =IF(R20<>0,(AP20+AS20)/R20,"") | AU20: =IF(R20<>0,(AT20/AVERAGE(AT:AT))-100%,"") | AV20: =IF(R20<>0,AP20+AQ20+AS20,"")
A21: 10 | AN21: =IF(R21<>0,AM21/R21,"") | AQ21: =IF(R21<>0,5.5%*AP21,"") | AR21: =IFERROR(AP21/R21,"") | AS21: =IF(AC21="Não tem",$AC$9)+IF(AB21="Não tem",$AB$9)+IF(AA21="Não tem",$AA$9)+IF(Z21="Não tem",$Z$9)+IF(Y21="Não tem",$Y$9)+IF(X21="Não tem",$X$9)+IF(W21="Não tem",$W$9)+IF(V21="Não tem",$V$9)+IF(U21="Aberta",$U$9)+IF(T21="Contrapiso",$T$9) -> 0 | AT21: =IF(R21<>0,(AP21+AS21)/R21,"") | AU21: =IF(R21<>0,(AT21/AVERAGE(AT:AT))-100%,"") | AV21: =IF(R21<>0,AP21+AQ21+AS21,"")
A22: 11 | AN22: =IF(R22<>0,AM22/R22,"") | AQ22: =IF(R22<>0,5.5%*AP22,"") | AR22: =IFERROR(AP22/R22,"") | AS22: =IF(AC22="Não tem",$AC$9)+IF(AB22="Não tem",$AB$9)+IF(AA22="Não tem",$AA$9)+IF(Z22="Não tem",$Z$9)+IF(Y22="Não tem",$Y$9)+IF(X22="Não tem",$X$9)+IF(W22="Não tem",$W$9)+IF(V22="Não tem",$V$9)+IF(U22="Aberta",$U$9)+IF(T22="Contrapiso",$T$9) -> 0 | AT22: =IF(R22<>0,(AP22+AS22)/R22,"") | AU22: =IF(R22<>0,(AT22/AVERAGE(AT:AT))-100%,"") | AV22: =IF(R22<>0,AP22+AQ22+AS22,"")
A23: 12 | AN23: =IF(R23<>0,AM23/R23,"") | AQ23: =IF(R23<>0,5.5%*AP23,"") | AR23: =IFERROR(AP23/R23,"") | AS23: =IF(AC23="Não tem",$AC$9)+IF(AB23="Não tem",$AB$9)+IF(AA23="Não tem",$AA$9)+IF(Z23="Não tem",$Z$9)+IF(Y23="Não tem",$Y$9)+IF(X23="Não tem",$X$9)+IF(W23="Não tem",$W$9)+IF(V23="Não tem",$V$9)+IF(U23="Aberta",$U$9)+IF(T23="Contrapiso",$T$9) -> 0 | AT23: =IF(R23<>0,(AP23+AS23)/R23,"") | AU23: =IF(R23<>0,(AT23/AVERAGE(AT:AT))-100%,"") | AV23: =IF(R23<>0,AP23+AQ23+AS23,"")
A24: 13 | AN24: =IF(R24<>0,AM24/R24,"") | AQ24: =IF(R24<>0,5.5%*AP24,"") | AR24: =IFERROR(AP24/R24,"") | AS24: =IF(AC24="Não tem",$AC$9)+IF(AB24="Não tem",$AB$9)+IF(AA24="Não tem",$AA$9)+IF(Z24="Não tem",$Z$9)+IF(Y24="Não tem",$Y$9)+IF(X24="Não tem",$X$9)+IF(W24="Não tem",$W$9)+IF(V24="Não tem",$V$9)+IF(U24="Aberta",$U$9)+IF(T24="Contrapiso",$T$9) -> 0 | AT24: =IF(R24<>0,(AP24+AS24)/R24,"") | AU24: =IF(R24<>0,(AT24/AVERAGE(AT:AT))-100%,"") | AV24: =IF(R24<>0,AP24+AQ24+AS24,"")
A25: 14 | AN25: =IF(R25<>0,AM25/R25,"") | AQ25: =IF(R25<>0,5.5%*AP25,"") | AR25: =IFERROR(AP25/R25,"") | AS25: =IF(AC25="Não tem",$AC$9)+IF(AB25="Não tem",$AB$9)+IF(AA25="Não tem",$AA$9)+IF(Z25="Não tem",$Z$9)+IF(Y25="Não tem",$Y$9)+IF(X25="Não tem",$X$9)+IF(W25="Não tem",$W$9)+IF(V25="Não tem",$V$9)+IF(U25="Aberta",$U$9)+IF(T25="Contrapiso",$T$9) -> 0 | AT25: =IF(R25<>0,(AP25+AS25)/R25,"") | AU25: =IF(R25<>0,(AT25/AVERAGE(AT:AT))-100%,"") | AV25: =IF(R25<>0,AP25+AQ25+AS25,"")
... A41: 30 | AN41: =IF(R41<>0,AM41/R41,"") | AQ41: =IF(R41<>0,5.5%*AP41,"") | AR41: =IFERROR(AP41/R41,"") | AS41: =IF(AC41="Não tem",$AC$9)+IF(AB41="Não tem",$AB$9)+IF(AA41="Não tem",$AA$9)+IF(Z41="Não tem",$Z$9)+IF(Y41="Não tem",$Y$9)+IF(X41="Não tem",$X$9)+IF(W41="Não tem",$W$9)+IF(V41="Não tem",$V$9)+IF(U41="Aberta",$U$9)+IF(T41="Contrapiso",$T$9) -> 0 | AT41: =IF(R41<>0,(AP41+AS41)/R41,"") | AU41: =IF(R41<>0,(AT41/AVERAGE(AT:AT))-100%,"") | AV41: =IF(R41<>0,AP41+AQ41+AS41,"")

Sheet 10.1-Pesquisa Locação
B1: © Escola de Imóveis - www.escoladeimoveis.com.br | Siga no instagram e tenha o melhor conteúdo: @escoladeimoveis
B2: É terminantemente proibida a utilização, acesso, cópia ou divulgação não autorizada das informações presentes nesta planilha.
B3: ATENÇÃO: SOMENTE ALTERAR AS CÉLULAS ROXAS COM A ESCRITA FAÇA VOCÊ
B5: Pesquisa de Mercado Compra
C7: Faça Você | E7: Faça Você | G7: FI | H7: Faça Você
B8: Pacote Médio | C8: =AVERAGE(AS:AS) -> 2263 | D8: M² Pacote | E8: =AVERAGE(AU:AU) -> 87.038462 | F8: Índice Comparativo | T8: Estimativa Custo Adicional Studio
T9: =100*R12 -> 2600 | U9: 4500 | V9: 500 | W9: 1500 | X9: 500 | Y9: 2500 | Z9: 8000 | AA9: 1000 | AB9: 1000 | AC9: 1000
B10: Endereço | H10: Configuração do Apartamento | T10: Características do Apartamento | AD10: Característicad do Condomínio | AM10: Características Financeiras do Imóvel
B11: Av/Rua | C11: Número | D11: Bairro | E11: Metrô | F11: Condomínio | G11: Link | H11: Dormitórios | I11: Banheiros | J11: Suíte | K11: Vaga | L11: Andar | M11: Posição | N11: Vista | O11: Visual | P11: Aspecto | Q11: Ano Construção | R11: M² Privativo | S11: Parede | T11: Piso | U11: Sacada | V11: Box | W11: Chuveiro | X11: Persiana | Y11: Ar Condicionado | Z11: Mar. Cozinha | AA11: Mar. Banheiro | AB11: Mar. Quarto | AC11: Cooktop | AD11: Portaria | AE11: Lavanderia | AF11: Academia | AG11: Salão de Festas | AH11: Coworking | AI11: Piscina | AJ11: Pet Place | AK11: Bicicletário | AL11: Rooftop | AM11: Condomínio | AN11: Cond/M² | AO11: IPTU Mês | AP11: Seguro | AQ11: Locação | AR11: M² Locação | AS11: Pacote | AT11: Var Pacote | AU11: M² Pacote | AV11: Var M² Pacote
A12: 1 | B12: Av Duque de Caxias | C12: 61 | D12: Centro | E12: 100m | F12: Smart Santa Cecília | H12: 0 | I12: 1 | J12: 0 | K12: 0 | L12: 4 | M12: Norte | N12: Lateral | O12: Livre | P12: Novo | Q12: 2018 | R12: 26 | S12: Drywall | T12: Porcelanato | U12: Aberta | V12: Vidro | W12: Gás Individual | X12: Interna | Y12: Quarto/Sala | Z12: Sim | AA12: Sim | AB12: Sim | AC12: Não tem | AD12: 24h | AE12: Industrial | AF12: Simples | AG12: Gourmet | AH12: Pequeno | AI12: Externa | AJ12: Sim | AK12: Com bicicletas | AL12: Sim | AM12: 308 | AN12: =IF(R12<>0,AM12/R12,"") -> 11.846154 | AO12: 55 | AP12: =IF(R12<>0,1.3%*AQ12,"") -> 24.7 | AQ12: 1900 | AR12: =IF(R12<>0,AQ12/R12,"") -> 73.076923 | AS12: =IF(R12<>0,AM12+AO12+AQ12,"") -> 2263 | AT12: =IF(R12<>0,(AS12/AVERAGE(AS:AS))-100%,"") -> 0 | AU12: =IF(R12<>0,AS12/R12,"") -> 87.038462 | AV12: =IF(R12<>0,(AU12/AVERAGE(AU:AU))-100%,"") -> 0
A13: 2 | AN13: =IF(R13<>0,AM13/R13,"") | AP13: =IF(R13<>0,1.3%*AQ13,"") | AR13: =IF(R13<>0,AQ13/R13,"") | AS13: =IF(R13<>0,AM13+AO13+AQ13,"") | AT13: =IF(R13<>0,(AS13/AVERAGE(AS:AS))-100%,"") | AU13: =IF(R13<>0,AS13/R13,"") | AV13: =IF(R13<>0,(AU13/AVERAGE(AU:AU))-100%,"")
A14: 3 | AN14: =IF(R14<>0,AM14/R14,"") | AP14: =IF(R14<>0,1.3%*AQ14,"") | AR14: =IF(R14<>0,AQ14/R14,"") | AS14: =IF(R14<>0,AM14+AO14+AQ14,"") | AT14: =IF(R14<>0,(AS14/AVERAGE(AS:AS))-100%,"") | AU14: =IF(R14<>0,AS14/R14,"") | AV14: =IF(R14<>0,(AU14/AVERAGE(AU:AU))-100%,"")
A15: 4 | AN15: =IF(R15<>0,AM15/R15,"") | AP15: =IF(R15<>0,1.3%*AQ15,"") | AR15: =IF(R15<>0,AQ15/R15,"") | AS15: =IF(R15<>0,AM15+AO15+AQ15,"") | AT15: =IF(R15<>0,(AS15/AVERAGE(AS:AS))-100%,"") | AU15: =IF(R15<>0,AS15/R15,"") | AV15: =IF(R15<>0,(AU15/AVERAGE(AU:AU))-100%,"")
A16: 5 | AN16: =IF(R16<>0,AM16/R16,"") | AP16: =IF(R16<>0,1.3%*AQ16,"") | AR16: =IF(R16<>0,AQ16/R16,"") | AS16: =IF(R16<>0,AM16+AO16+AQ16,"") | AT16: =IF(R16<>0,(AS16/AVERAGE(AS:AS))-100%,"") | AU16: =IF(R16<>0,AS16/R16,"") | AV16: =IF(R16<>0,(AU16/AVERAGE(AU:AU))-100%,"")
A17: 6 | AN17: =IF(R17<>0,AM17/R17,"") | AP17: =IF(R17<>0,1.3%*AQ17,"") | AR17: =IF(R17<>0,AQ17/R17,"") | AS17: =IF(R17<>0,AM17+AO17+AQ17,"") | AT17: =IF(R17<>0,(AS17/AVERAGE(AS:AS))-100%,"") | AU17: =IF(R17<>0,AS17/R17,"") | AV17: =IF(R17<>0,(AU17/AVERAGE(AU:AU))-100%,"")
A18: 7 | AN18: =IF(R18<>0,AM18/R18,"") | AP18: =IF(R18<>0,1.3%*AQ18,"") | AR18: =IF(R18<>0,AQ18/R18,"") | AS18: =IF(R18<>0,AM18+AO18+AQ18,"") | AT18: =IF(R18<>0,(AS18/AVERAGE(AS:AS))-100%,"") | AU18: =IF(R18<>0,AS18/R18,"") | AV18: =IF(R18<>0,(AU18/AVERAGE(AU:AU))-100%,"")
A19: 8 | AN19: =IF(R19<>0,AM19/R19,"") | AP19: =IF(R19<>0,1.3%*AQ19,"") | AR19: =IF(R19<>0,AQ19/R19,"") | AS19: =IF(R19<>0,AM19+AO19+AQ19,"") | AT19: =IF(R19<>0,(AS19/AVERAGE(AS:AS))-100%,"") | AU19: =IF(R19<>0,AS19/R19,"") | AV19: =IF(R19<>0,(AU19/AVERAGE(AU:AU))-100%,"")
A20: 9 | AN20: =IF(R20<>0,AM20/R20,"") | AP20: =IF(R20<>0,1.3%*AQ20,"") | AR20: =IF(R20<>0,AQ20/R20,"") | AS20: =IF(R20<>0,AM20+AO20+AQ20,"") | AT20: =IF(R20<>0,(AS20/AVERAGE(AS:AS))-100%,"") | AU20: =IF(R20<>0,AS20/R20,"") | AV20: =IF(R20<>0,(AU20/AVERAGE(AU:AU))-100%,"")
A21: 10 | AN21: =IF(R21<>0,AM21/R21,"") | AP21: =IF(R21<>0,1.3%*AQ21,"") | AR21: =IF(R21<>0,AQ21/R21,"") | AS21: =IF(R21<>0,AM21+AO21+AQ21,"") | AT21: =IF(R21<>0,(AS21/AVERAGE(AS:AS))-100%,"") | AU21: =IF(R21<>0,AS21/R21,"") | AV21: =IF(R21<>0,(AU21/AVERAGE(AU:AU))-100%,"")
A22: 11 | AN22: =IF(R22<>0,AM22/R22,"") | AP22: =IF(R22<>0,1.3%*AQ22,"") | AR22: =IF(R22<>0,AQ22/R22,"") | AS22: =IF(R22<>0,AM22+AO22+AQ22,"") | AT22: =IF(R22<>0,(AS22/AVERAGE(AS:AS))-100%,"") | AU22: =IF(R22<>0,AS22/R22,"") | AV22: =IF(R22<>0,(AU22/AVERAGE(AU:AU))-100%,"")
A23: 12 | AN23: =IF(R23<>0,AM23/R23,"") | AP23: =IF(R23<>0,1.3%*AQ23,"") | AR23: =IF(R23<>0,AQ23/R23,"") | AS23: =IF(R23<>0,AM23+AO23+AQ23,"") | AT23: =IF(R23<>0,(AS23/AVERAGE(AS:AS))-100%,"") | AU23: =IF(R23<>0,AS23/R23,"") | AV23: =IF(R23<>0,(AU23/AVERAGE(AU:AU))-100%,"")
A24: 13 | AN24: =IF(R24<>0,AM24/R24,"") | AP24: =IF(R24<>0,1.3%*AQ24,"") | AR24: =IF(R24<>0,AQ24/R24,"") | AS24: =IF(R24<>0,AM24+AO24+AQ24,"") | AT24: =IF(R24<>0,(AS24/AVERAGE(AS:AS))-100%,"") | AU24: =IF(R24<>0,AS24/R24,"") | AV24: =IF(R24<>0,(AU24/AVERAGE(AU:AU))-100%,"")
... A41: 30 | AN41: =IF(R41<>0,AM41/R41,"") | AP41: =IF(R41<>0,1.3%*AQ41,"") | AR41: =IF(R41<>0,AQ41/R41,"") | AS41: =IF(R41<>0,AM41+AO41+AQ41,"") | AT41: =IF(R41<>0,(AS41/AVERAGE(AS:AS))-100%,"") | AU41: =IF(R41<>0,AS41/R41,"") | AV41: =IF(R41<>0,(AU41/AVERAGE(AU:AU))-100%,"")

Sheet 11-Viabilidade
B1: © Escola de Imóveis - www.escoladeimoveis.com.br | Siga no instagram e tenha o melhor conteúdo: @escoladeimoveis | J1: 11/12/2022 - V2-2.1 - Ajustado erro do ponto e virgula dos números de seleção.
B2: É terminantemente proibida a utilização, acesso, cópia ou divulgação não autorizada das informações presentes nesta planilha. | J2: 14/02/2024 - V2-2.2 - Adicionado campos para cáculo de aluguel de Airbnb
B3: ATENÇÃO: SOMENTE ALTERAR AS CÉLULAS ROXAS COM A ESCRITA FAÇA VOCÊ | J3: 15/02/2024 - V2-2.3 - Ajustado erro na fórmula de vacância.
B5: Viabilidade
B7: Premissas de Compra (Pronto) | F7: Premissas de Compra (Planta) | J7: Premissas de Locação e Operação | N7: Premissas de Venda e Mercado
C9: Faça Você | G9: Faça Você | K9: Faça Você | O9: Faça Você
B10: Valor Imóvel | C10: 300000 | F10: Compra planta? | G10: Não | J10: Aluguel | K10: 3000 | N10: Inflação Aluguel | O10: 0.05 | P10: =(1+O10)^(1/12)-1 -> 0.0040741238
B11: LTV | C11: 0.8 | F11: Prazo Obra | G11: 12 | J11: Vacância Mês | K11: 2 | L11: =((K11*K10)/K13)+((K16+K17)*K11)/K13 -> 392.22222 | N11: Valorização Imóvel | O11: 0.05
B12: Taxa Anual | C12: 0.1 | F12: INCC | G12: 0.04 | H12: =(1+G12)^(1/12)-1 -> 0.0032737398 | J12: Corretagem | K12: 1 | L12: =K12/K13 -> 0.055555556 | N12: Reforma 10º Ano | O12: 0
B13: Tamanho (m²) | C13: 25 | F13: Pagamento Obra | G13: =IF(G10="Sim",C15,0) -> 0 | J13: Tempo Contrato | K13: 18 | N13: Comissão Venda | O13: 0
B14: Empréstimo | C14: =IF($G$10="Não",$C$10*$C$11,((($C$10*$C$11)*(1+$G$12)^(($G$11+1)/12)))) -> 240000 | F14: Entrada | G14: =G13*G19 -> 0 | J14: Adm Mensal | K14: 0 | N14: Saída (Ano) | O14: 15 | P14: =O14*12 -> 180
B15: Entrada | C15: =C10*(100%-C11) -> 60000 | F15: 1ª Parcela Mensal | G15: =(G20*G13)/G11 -> 0 | J15: Fundo Reparos | K15: 0.05 | N15: Custo Capital | O15: 0.1
F16: Chaves | G16: =G13*G21 -> 0 | J16: IPTU | K16: 80 | N16: IR Renda | O16: 0.15
J17: Condomínio | K17: 450 | N17: IR Venda | O17: 0
C18: Faça Você | G18: Faça Você
B19: ITBI | C19: 0.03 | D19: =C19*C10 -> 9000 | F19: Entrada | G19: 0.1 | J19: Para Airbnb (Usar para calcular aluguel)
B20: Escritura | C20: 0 | D20: =C20*C10 -> 0 | F20: Parcelas Obra | G20: 0.8
B21: Registro | C21: 0.02 | D21: =C21*C10 -> 6000 | F21: Chaves | G21: 0.1 | K21: Faça Você
B22: Avaliação | C22: 1500 | F22: Total (100%) | G22: =SUM(G19:G21) -> 1 | J22: Diária Média | K22: 150 | W22: Comparador de Cenários (Teste as variações do modelo)
B23: Reforma Inicial | C23: 50000 | F23: *Para calcular certo a parcela de chaves não pode ser 0% | J23: Ocupação Média | K23: 0.85 | L23: =K23*30 -> 25.5 | W23: Mto. Pessimista | X23: Pessimista | Y23: Normal | Z23: Otimista | AA23: Mto. otimista
B24: Prazo Reforma | C24: 6 | J24: Administrador | K24: 0.15 | W24: Cenário A | X24: Cenário B | Y24: Cenário C | Z24: Cenário D | AA24: Cenário E
B25: Custo Alavancado | C25: =C15+D19+D21+C22+C23 -> 126500 | J25: Luz/Gás | K25: 100 | V25: Valor Imóvel
B26: Custo Total | C26: =C10+D19+D20+D21+C23 -> 365000 | J26: Internet | K26: 100 | V26: LTV
B27: Custo m² Compra | C27: =(C14+C15)/C13 -> 12000 | J27: Outros | K27: 0 | V27: INCC
B28: Custo m² Total | C28: =(C23+D21+D20+D19+C15+C14)/C13 -> 14600 | J28: IPTU | K28: =K16 -> 80 | V28: Aluguel
J29: Condomínio | K29: =K17 -> 450 | V29: Vacância Mês
J30: Aluguel Airbnb | K30: =(((K22*L23)*(100%-K24))-(K25+K26+K27+K28+K29)) -> 2521.25 | V30: Corretagem
B31: Imóvel Pronto | J31: Limpeza foi considerada paga com a taxa de limpeza | V31: Adm Mensal
C32: Faça Você | D32: Faça Você
C33: Valor de Mercado | D33: 0 | E33: 0 | F33: 0 | G33: 0 | H33: 0 | I33: 0 | J33: 0 | K33: 0 | L33: 0 | M33: 0 | N33: 0 | O33: 0 | P33: 0 | Q33: 0
C34: =$C$10+$C$23 -> 350000 | D34: =IF(D33<C34,(C34+(C34*$O$11)),D33) -> 367500 | E34: =IF(E33<D34,(D34+(D34*$O$11)),E33) -> 385875 | F34: =IF(F33<E34,(E34+(E34*$O$11)),F33) -> 405168.75 | G34: =IF(G33<F34,(F34+(F34*$O$11)),G33) -> 425427.19 | H34: =IF(H33<G34,(G34+(G34*$O$11)),H33) -> 446698.55 | I34: =IF(I33<H34,(H34+(H34*$O$11)),I33) -> 469033.47 | J34: =IF(J33<I34,(I34+(I34*$O$11)),J33) -> 492485.15 | K34: =IF(K33<J34,(J34+(J34*$O$11)),K33) -> 517109.41 | ... Q34: =IF(Q33<P34,(P34+(P34*$O$11)),Q33) -> 692976.06
B35: À Vista | C35: 1º Ano | D35: 2º Ano | E35: 3º Ano | F35: 4º Ano | G35: 5º Ano | H35: 6º Ano | I35: 7º Ano | J35: 8º Ano | K35: 9º Ano | L35: 10º Ano | M35: 11º Ano | N35: 12º Ano | O35: 13º Ano | P35: 14º Ano | Q35: 15º Ano | S35: Indicadores À Vista
B36: Investimento | C36: =-($D$19+$D$20+$D$21+$C$10+$C$23) -> -365000 | S36: TIR | T36: =IRR(C39:Q39) -> 0.11387441 | V36: TIR
B37: Renda | C37: =IF($O$14>=1,SUM('11.1 - Auxiliar Viabilidade'!$M$8:$M$19),0) -> 7979.7934 | D37: =IF($O$14>=2,SUM('11.1 - Auxiliar Viabilidade'!$M$20:$M$31),0) -> 23153.169 | E37: =IF($O$14>=3,SUM('11.1 - Auxiliar Viabilidade'!$M$32:$M$43),0) -> 24310.827 | F37: =IF($O$14>=4,SUM('11.1 - Auxiliar Viabilidade'!$M$44:$M$55),0) -> 25526.368 | G37: =IF($O$14>=5,SUM('11.1 - Auxiliar Viabilidade'!$M$56:$M$67),0) -> 26802.687 | H37: =IF($O$14>=6,SUM('11.1 - Auxiliar Viabilidade'!$M$68:$M$79),0) -> 28142.821 | I37: =IF($O$14>=7,SUM('11.1 - Auxiliar Viabilidade'!$M$80:$M$91),0) -> 29549.962 | J37: =IF($O$14>=8,SUM('11.1 - Auxiliar Viabilidade'!$M$92:$M$103),0) -> 31027.46 | K37: =IF($O$14>=9,SUM('11.1 - Auxiliar Viabilidade'!$M$104:$M$115),0) -> 32578.833 | L37: =IF($O$14>=10,SUM('11.1 - Auxiliar Viabilidade'!$M$116:$M$127)-$O$12,0) -> 34207.775 | M37: =IF($O$14>=11,SUM('11.1 - Auxiliar Viabilidade'!$M$128:$M$139),0) -> 35918.164 | N37: =IF($O$14>=12,SUM('11.1 - Auxiliar Viabilidade'!$M$140:$M$151),0) -> 37714.072 | O37: =IF($O$14>=13,SUM('11.1 - Auxiliar Viabilidade'!$M$152:$M$163),0) -> 39599.775 | P37: =IF($O$14>=14,SUM('11.1 - Auxiliar Viabilidade'!$M$164:$M$175),0) -> 41579.764 | Q37: =IF($O$14>=15,SUM('11.1 - Auxiliar Viabilidade'!$M$176:$M$187),0) -> 43658.752 | S37: ROI | T37: =((SUM(D39:Q39)+C39)/-C39) -> 2.2119932 | V37: ROI
B38: Venda | C38: =IF($O$14=1,C34-((C34*$O$13)+$O$17*(C34-$C$10)),0) -> 0 | D38: =IF($O$14=2,D34-((D34*$O$13)+$O$17*(D34-$C$10)),0) -> 0 | E38: =IF($O$14=3,E34-((E34*$O$13)+$O$17*(E34-$C$10)),0) -> 0 | F38: =IF($O$14=4,F34-((F34*$O$13)+$O$17*(F34-$C$10)),0) -> 0 | G38: =IF($O$14=5,G34-((G34*$O$13)+$O$17*(G34-$C$10)),0) -> 0 | H38: =IF($O$14=6,H34-((H34*$O$13)+$O$17*(H34-$C$10)),0) -> 0 | I38: =IF($O$14=7,I34-((I34*$O$13)+$O$17*(I34-$C$10)),0) -> 0 | J38: =IF($O$14=8,J34-((J34*$O$13)+$O$17*(J34-$C$10)),0) -> 0 | K38: =IF($O$14=9,K34-((K34*$O$13)+$O$17*(K34-$C$10)),0) -> 0 | L38: =IF($O$14=10,L34-((L34*$O$13)+$O$17*(L34-$C$10)),0) -> 0 | M38: =IF($O$14=11,M34-((M34*$O$13)+$O$17*(M34-$C$10)),0) -> 0 | N38: =IF($O$14=12,N34-((N34*$O$13)+$O$17*(N34-$C$10)),0) -> 0 | O38: =IF($O$14=13,O34-((O34*$O$13)+$O$17*(O34-$C$10)),0) -> 0 | P38: =IF($O$14=14,P34-((P34*$O$13)+$O$17*(P34-$C$10)),0) -> 0 | Q38: =IF($O$14=15,$Q$34-(($Q$34*$O$13)+$O$17*($Q$34-$C$10)),0) -> 692976.06 | S38: Multiplo | T38: =SUM(D39:Q39)/-C39 -> 3.2119932 | V38: Multiplo
B39: Fluxo | C39: =SUM(C36:C38) -> -357020.21 | D39: =SUM(D36:D38) -> 23153.169 | E39: =SUM(E36:E38) -> 24310.827 | F39: =SUM(F36:F38) -> 25526.368 | G39: =SUM(G36:G38) -> 26802.687 | H39: =SUM(H36:H38) -> 28142.821 | I39: =SUM(I36:I38) -> 29549.962 | J39: =SUM(J36:J38) -> 31027.46 | ... Q39: =SUM(Q36:Q38) -> 736634.81 | S39: VPL | T39: {=NPV($O$15,D39:Q39)+C39} -> 47094.424 | V39: VPL
B40: Yield | C40: =C37/-$C$36 -> 0.021862448 | D40: =IF($C$37<0,-D37/$C$39,-D37/$C$36) -> 0.063433338 | E40: =IF($C$37<0,-E37/$C$39,-E37/$C$36) -> 0.066605005 | F40: =IF($C$37<0,-F37/$C$39,-F37/$C$36) -> 0.069935256 | G40: =IF($C$37<0,-G37/$C$39,-G37/$C$36) -> 0.073432018 | H40: =IF($C$37<0,-H37/$C$39,-H37/$C$36) -> 0.077103619 | I40: =IF($C$37<0,-I37/$C$39,-I37/$C$36) -> 0.0809588 | J40: =IF($C$37<0,-J37/$C$39,-J37/$C$36) -> 0.08500674 | K40: =IF($C$37<0,-K37/$C$39,-K37/$C$36) -> 0.089257077 | ... Q40: =IF($C$37<0,-Q37/$C$39,-Q37/$C$36) -> 0.11961302
B42: Alavancagem | C42: 1º Ano | D42: 2º Ano | E42: 3º Ano | F42: 4º Ano | G42: 5º Ano | H42: 6º Ano | I42: 7º Ano | J42: 8º Ano | K42: 9º Ano | L42: 10º Ano | M42: 11º Ano | N42: 12º Ano | O42: 13º Ano | P42: 14º Ano | Q42: 15º Ano | S42: Indicadores Alavancado
B43: Investimento | C43: =-($C$15+$D$19+$D$21+$C$22+$C$23) -> -126500 | S43: TIR Ala. | T43: =IRR(C46:Q46) -> 0.1153716 | V43: TIR Ala.
B44: Renda | C44: =IF($O$14>=1,SUM('11.1 - Auxiliar Viabilidade'!$L$8:$L$19),0) -> -21542.135 | D44: =IF($O$14>=2,SUM('11.1 - Auxiliar Viabilidade'!$L$20:$L$31),0) -> -5712.6019 | E44: =IF($O$14>=3,SUM('11.1 - Auxiliar Viabilidade'!$L$32:$L$43),0) -> -3898.7856 | F44: =IF($O$14>=4,SUM('11.1 - Auxiliar Viabilidade'!$L$44:$L$55),0) -> -2027.0865 | G44: =IF($O$14>=5,SUM('11.1 - Auxiliar Viabilidade'!$L$56:$L$67),0) -> -94.610205 | H44: =IF($O$14>=6,SUM('11.1 - Auxiliar Viabilidade'!$L$68:$L$79),0) -> 1901.682 | I44: =IF($O$14>=7,SUM('11.1 - Auxiliar Viabilidade'!$L$80:$L$91),0) -> 3964.9809 | J44: =IF($O$14>=8,SUM('11.1 - Auxiliar Viabilidade'!$L$92:$L$103),0) -> 6098.6368 | K44: =IF($O$14>=9,SUM('11.1 - Auxiliar Viabilidade'!$L$104:$L$115),0) -> 8306.1677 | L44: =IF($O$14>=10,SUM('11.1 - Auxiliar Viabilidade'!$L$116:$L$127)-$O$12,0) -> 10591.267 | M44: =IF($O$14>=11,SUM('11.1 - Auxiliar Viabilidade'!$L$128:$L$139),0) -> 12957.814 | N44: =IF($O$14>=12,SUM('11.1 - Auxiliar Viabilidade'!$L$140:$L$151),0) -> 15409.88 | O44: =IF($O$14>=13,SUM('11.1 - Auxiliar Viabilidade'!$L$152:$L$163),0) -> 17951.741 | P44: =IF($O$14>=14,SUM('11.1 - Auxiliar Viabilidade'!$L$164:$L$175),0) -> 20587.888 | Q44: =IF($O$14>=15,SUM('11.1 - Auxiliar Viabilidade'!$L$176:$L$187),0) -> 23323.034 | S44: ROI Ala. | T44: =((SUM(D46:Q46)+C46)/-C46) -> 3.4932695 | V44: ROI Ala.
...

Sheet 11.1 - Auxiliar Viabilidade
B1: © Escola de Imóveis - www.escoladeimoveis.com.br | Siga no instagram e tenha o melhor conteúdo: @escoladeimoveis
B2: É terminantemente proibida a utilização, acesso, cópia ou divulgação não autorizada das informações presentes nesta planilha.
B3: ATENÇÃO: SOMENTE ALTERAR AS CÉLULAS ROXAS COM A ESCRITA FAÇA VOCÊ
B5: Auxiliar Viabilidade Completa
B7: Mês | C7: Offset Mês | D7: Aluguel | E7: Corretagem | F7: Administração | G7: Fundo Reparos | H7: Vacância | I7: Prestação | J7: Saldo Devedor | K7: Imposto | L7: Líquido Alavan. | M7: Líquido À Vista | O7: Entrada | P7: Parcelas Obra | Q7: Parcela Entrega | R7: Total Planta | S7: Mês Ajustado | T7: Offset Planta | U7: Aluguel | V7: Corretagem | W7: Administração | X7: Fundo Reparos | Y7: Vacância | Z7: Prestação | AA7: Saldo Devedor | AB7: Imposto | AC7: Líquido Alavan. | AD7: Líquido À Vista
A8: =IF(AND('11-Viabilidade'!P14>0,'11-Viabilidade'!P14<421),1,0) -> 1 | B8: =IF(A8>0,1,0) -> 1 | C8: =IF($B8<'11-Viabilidade'!$C$24,0,$B8-'11-Viabilidade'!$C$24) -> 0 | D8: =IF(C8>0,'11-Viabilidade'!$K$10,0)*((1+'11-Viabilidade'!$O$10)^(($C8-1)/12)) -> 0 | E8: =D8*'11-Viabilidade'!$L$12 -> 0 | F8: =D8*'11-Viabilidade'!$K$14 -> 0 | G8: =D8*'11-Viabilidade'!$K$15 -> 0 | H8: =IF(D8=0,'11-Viabilidade'!$K$16+'11-Viabilidade'!$K$17,('11-Viabilidade'!$L$11)*((1+'11-Viabilidade'!$O$10)^(($C8-1)/12))) -> 530 | I8: ='12-SAC Viabilidade'!G11 -> 2485.2223 | J8: ='12-SAC Viabilidade'!H11 -> 239428.57 | K8: =(D8-F8)*'11-Viabilidade'!$O$16 -> 0 | L8: =D8-(E8+F8+G8+H8+I8+K8) -> -3015.2223 | M8: =D8-(E8+F8+G8+H8+K8) -> -530 | O8: =IF('11-Viabilidade'!G10="Sim",'11-Viabilidade'!G14,0) -> 0 | P8: =IF(B8<='11-Viabilidade'!$G$11,'11-Viabilidade'!$G$15,0) -> 0 | Q8: =IF(B8='11-Viabilidade'!$G$11,'11-Viabilidade'!$G$16,0)*(1+'11-Viabilidade'!$G$12)^((B8-1)/12) -> 0 | R8: =-SUM(O8:Q8) -> 0 | S8: =IF(R8<>0,0,1) -> 1 | T8: =IF($S8<'11-Viabilidade'!$C$24,0,$S8-'11-Viabilidade'!$C$24) -> 0 | U8: =IF(T8>0,'11-Viabilidade'!$K$10,0)*((1+'11-Viabilidade'!$O$10)^(($T8-1)/12)) -> 0 | V8: =U8*'11-Viabilidade'!$L$12 -> 0 | W8: =U8*'11-Viabilidade'!$K$14 -> 0 | X8: =U8*'11-Viabilidade'!$K$15 -> 0 | Y8: =IF(AND(U8=0,S8=0),0,IF(AND(U8=0,S8<>0),'11-Viabilidade'!$K$16+'11-Viabilidade'!$K$17,('11-Viabilidade'!$L$11)*((1+'11-Viabilidade'!$O$10)^(($C8-1)/12)))) -> 530 | Z8: =IFERROR(VLOOKUP(S8,'12-SAC Viabilidade'!$B$11:$G$430,6,FALSE),0) -> 2485.2223 | AA8: =IFERROR(VLOOKUP(S8,'12-SAC Viabilidade'!$B$11:$H$430,7,FALSE),0) -> 239428.57 | AB8: =(U8-W8)*'11-Viabilidade'!$O$16 -> 0 | AC8: =U8-(V8+W8+X8+Y8+Z8+AB8-R8) -> -3015.2223 | AD8: =U8-(V8+W8+X8+Y8+AB8) -> -530
B9: =IF(AND(B8>0,B8<'11-Viabilidade'!$P$14),B8+1,0) -> 2 | C9: =IF($B9<'11-Viabilidade'!$C$24,0,$B9-'11-Viabilidade'!$C$24) -> 0 | D9: =IF(C9>0,'11-Viabilidade'!$K$10,0)*((1+'11-Viabilidade'!$O$10)^(($C9-1)/12)) -> 0 | E9: =D9*'11-Viabilidade'!$L$12 -> 0 | F9: =D9*'11-Viabilidade'!$K$14 -> 0 | G9: =D9*'11-Viabilidade'!$K$15 -> 0 | H9: =IF(D9=0,'11-Viabilidade'!$K$16+'11-Viabilidade'!$K$17,('11-Viabilidade'!$L$11)*((1+'11-Viabilidade'!$O$10)^(($C9-1)/12))) -> 530 | I9: ='12-SAC Viabilidade'!G12 -> 2480.6656 | J9: ='12-SAC Viabilidade'!H12 -> 238857.14 | K9: =(D9-F9)*'11-Viabilidade'!$O$16 -> 0 | L9: =D9-(E9+F9+G9+H9+I9+K9) -> -3010.6656 | M9: =D9-(E9+F9+G9+H9+K9) -> -530 | P9: =IF(B9<='11-Viabilidade'!$G$11,(P8+(P8*'11-Viabilidade'!$H$12)),0) -> 0 | Q9: =IF(B9='11-Viabilidade'!$G$11,'11-Viabilidade'!$G$16,0)*(1+'11-Viabilidade'!$G$12)^((B9-1)/12) -> 0 | R9: =-SUM(O9:Q9) -> 0 | S9: =IF(R9<>0,0,S8+1) -> 2 | T9: =IF($S9<'11-Viabilidade'!$C$24,0,$S9-'11-Viabilidade'!$C$24) -> 0 | U9: =IF(T9>0,'11-Viabilidade'!$K$10,0)*((1+'11-Viabilidade'!$O$10)^(($T9-1)/12)) -> 0 | V9: =U9*'11-Viabilidade'!$L$12 -> 0 | W9: =U9*'11-Viabilidade'!$K$14 -> 0 | X9: =U9*'11-Viabilidade'!$K$15 -> 0 | Y9: =IF(AND(U9=0,S9=0),0,IF(AND(U9=0,S9<>0),'11-Viabilidade'!$K$16+'11-Viabilidade'!$K$17,('11-Viabilidade'!$L$11)*((1+'11-Viabilidade'!$O$10)^(($C9-1)/12)))) -> 530 | Z9: =IFERROR(VLOOKUP(S9,'12-SAC Viabilidade'!$B$11:$G$430,6,FALSE),0) -> 2480.6656 | AA9: =IFERROR(VLOOKUP(S9,'12-SAC Viabilidade'!$B$11:$H$430,7,FALSE),0) -> 238857.14 | AB9: =(U9-W9)*'11-Viabilidade'!$O$16 -> 0 | AC9: =U9-(V9+W9+X9+Y9+Z9+AB9-R9) -> -3010.6656 | AD9: =U9-(V9+W9+X9+Y9+AB9) -> -530
B10: =IF(AND(B9>0,B9<'11-Viabilidade'!$P$14),B9+1,0) -> 3 | C10: =IF($B10<'11-Viabilidade'!$C$24,0,$B10-'11-Viabilidade'!$C$24) -> 0 | D10: =IF(C10>0,'11-Viabilidade'!$K$10,0)*((1+'11-Viabilidade'!$O$10)^(($C10-1)/12)) -> 0 | E10: =D10*'11-Viabilidade'!$L$12 -> 0 | F10: =D10*'11-Viabilidade'!$K$14 -> 0 | G10: =D10*'11-Viabilidade'!$K$15 -> 0 | H10: =IF(D10=0,'11-Viabilidade'!$K$16+'11-Viabilidade'!$K$17,('11-Viabilidade'!$L$11)*((1+'11-Viabilidade'!$O$10)^(($C10-1)/12))) -> 530 | I10: ='12-SAC Viabilidade'!G13 -> 2476.109 | J10: ='12-SAC Viabilidade'!H13 -> 238285.71 | K10: =(D10-F10)*'11-Viabilidade'!$O$16 -> 0 | L10: =D10-(E10+F10+G10+H10+I10+K10) -> -3006.109 | M10: =D10-(E10+F10+G10+H10+K10) -> -530 | P10: =IF(B10<='11-Viabilidade'!$G$11,(P9+(P9*'11-Viabilidade'!$H$12)),0) -> 0 | Q10: =IF(B10='11-Viabilidade'!$G$11,'11-Viabilidade'!$G$16,0)*(1+'11-Viabilidade'!$G$12)^((B10-1)/12) -> 0 | R10: =-SUM(O10:Q10) -> 0 | S10: =IF(R10<>0,0,S9+1) -> 3 | T10: =IF($S10<'11-Viabilidade'!$C$24,0,$S10-'11-Viabilidade'!$C$24) -> 0 | U10: =IF(T10>0,'11-Viabilidade'!$K$10,0)*((1+'11-Viabilidade'!$O$10)^(($T10-1)/12)) -> 0 | V10: =U10*'11-Viabilidade'!$L$12 -> 0 | W10: =U10*'11-Viabilidade'!$K$14 -> 0 | X10: =U10*'11-Viabilidade'!$K$15 -> 0 | Y10: =IF(AND(U10=0,S10=0),0,IF(AND(U10=0,S10<>0),'11-Viabilidade'!$K$16+'11-Viabilidade'!$K$17,('11-Viabilidade'!$L$11)*((1+'11-Viabilidade'!$O$10)^(($C10-1)/12)))) -> 530 | Z10: =IFERROR(VLOOKUP(S10,'12-SAC Viabilidade'!$B$11:$G$430,6,FALSE),0) -> 2476.109 | AA10: =IFERROR(VLOOKUP(S10,'12-SAC Viabilidade'!$B$11:$H$430,7,FALSE),0) -> 238285.71 | AB10: =(U10-W10)*'11-Viabilidade'!$O$16 -> 0 | AC10: =U10-(V10+W10+X10+Y10+Z10+AB10-R10) -> -3006.109 | AD10: =U10-(V10+W10+X10+Y10+AB10) -> -530
